Workbook

Sheet 生存汉语词汇表
A1: 序号 | B1: 课次 | C1: 课文 | D1: 汉字 | E1: 拼音 | F1: 英文解释 | G1: 例句1（中文） | H1: 例句1（英文） | I1: 例句2（中文） | J1: 例句2（英文） | K1: 备注 | L1: 最常见词语搭配
A2: 1 | B2: 4 | C2: 看菜单 | D2: 你好 | E2: nǐ hǎo | F2: hello; how are you | G2: 你好！ | H2: Hello! | I2: 老师，你好！ | J2: Hello, teacher! | L2: 你好老师；你好朋友；你好，请问
A3: 2 | B3: 4 | C3: 看菜单 | D3: 吃 | E3: chī | F3: eat | G3: 我想吃饭。 | H3: I want to eat. | I3: 我们可以吃饭吗？ | J3: Can we eat now? | L3: 吃饭；吃菜；吃早饭
A4: 3 | B4: 4 | C4: 看菜单 | D4: 什么 | E4: shénme | F4: what | G4: 这是什么？ | H4: What is this? | I4: 你吃什么？ | J4: What do you eat? | L4: 什么东西；什么时候；为什么
A5: 4 | B5: 4 | C5: 看菜单 | D5: 有（没有） | E5: yǒu (méiyǒu) | F5: have; exist (negative: not have) | G5: 这里有水。 | H5: There is water here. | I5: 这里没有咖啡。 | J5: There is no coffee here. | L5: 有时间；有朋友；没有问题
A6: 5 | B6: 4 | C6: 看菜单 | D6: 菜单 | E6: càidān | F6: menu | G6: 这是菜单。 | H6: This is the menu. | I6: 请给我看一下菜单。 | J6: Please show me the menu. | L6: 看菜单；菜单上；一份菜单
A7: 6 | B7: 4 | C7: 看菜单 | D7: 吗 | E7: ma | F7: question particle for yes/no questions | G7: 你好吗？ | H7: Are you well? | I7: 这里有水吗？ | J7: Is there water here? | L7: 好吗；有吗；可以吗
A8: 7 | B8: 4 | C8: 看菜单 | D8: 给 | E8: gěi | F8: give | G8: 请给我水。 | H8: Please give me water. | I8: 我给你一个。 | J8: I will give you one. | L8: 给我；给你；送给
A9: 8 | B9: 4 | C9: 看菜单 | D9: 这个 | E9: zhège | F9: this | G9: 这个很好。 | H9: This is very good. | I9: 我要这个。 | J9: I want this one. | L9: 这个人；这个地方；这个时候
A10: 9 | B10: 4 | C10: 看菜单 | D10: 叫 | E10: jiào | F10: call; be called | G10: 我叫小王。 | H10: My name is Xiao Wang. | I10: 我叫一辆车。 | J10: I will call a car. | L10: 叫名字；叫车；叫外卖
A11: 10 | B11: 4 | C11: 看菜单 | D11: 那个 | E11: nàge | F11: that | G11: 那个多少钱？ | H11: How much is that one? | I11: 我不要那个。 | J11: I do not want that one. | L11: 那个人；那个地方；那个时候
A12: 11 | B12: 4 | C12: 看菜单 | D12: 是 | E12: shì | F12: be; is/am/are | G12: 我是学生。 | H12: I am a student. | I12: 这是我的。 | J12: This is mine. | L12: 我是；这是；不是
A13: 12 | B13: 4 | C13: 看菜单 | D13: 要 | E13: yào | F13: want; would like | G13: 我要水。 | H13: I want water. | I13: 我要去学校。 | J13: I want to go to school. | L13: 想要；需要；要去
... A16: 15 | B16: 4 | C16: 看菜单 | D16: 这里 | E16: zhèlǐ | F16: here | G16: 我住这里。 | H16: I live here. | I16: 这里有地铁站。 | J16: There is a subway station here. | L16: 在这里；这里有；这里是
A17: 16 | B17: 4 | C17: 看菜单 | D17: 宫保鸡丁 | E17: gōngbǎo jīdīng | F17: kung pao chicken | G17: 我想吃宫保鸡丁。 | H17: I want to eat kung pao chicken. | I17: 我要一份宫保鸡丁。 | J17: I'd like one serving of kung pao chicken. | K17: 教材标*菜名 | L17: 吃宫保鸡丁；一份宫保鸡丁；喜欢宫保鸡丁
A18: 17 | B18: 4 | C18: 看菜单 | D18: 拉面 | E18: lāmiàn | F18: lamian; hand-pulled noodles | G18: 我想吃拉面。 | H18: I want to eat lamian. | I18: 我要一份拉面。 | J18: I'd like one serving of lamian. | K18: 教材标*菜名 | L18: 吃拉面；一份拉面；喜欢拉面
A19: 18 | B19: 4 | C19: 看菜单 | D19: 在 | E19: zài | F19: at; in; on | G19: 我在家。 | H19: I am at home. | I19: 他在学校。 | J19: He is at school. | L19: 在家；在学校；在这里
A20: 19 | B20: 4 | C20: 看菜单 | D20: 这儿 | E20: zhèr | F20: here | G20: 我在这儿。 | H20: I am here. | I20: 这儿有水。 | J20: There is water here. | L20: 在这儿；这儿有；来这儿
A21: 20 | B21: 4 | C21: 看菜单 | D21: 还是 | E21: háishì | F21: or (in a question) | G21: 你喝茶还是咖啡？ | H21: Do you drink tea or coffee? | I21: 坐地铁还是坐公交车？ | J21: Take the subway or the bus? | L21: 还是不；还是要；还是喜欢
A22: 21 | B22: 4 | C22: 看菜单 | D22: 打包 | E22: dǎbāo | F22: pack to go; take away | G22: 我想打包这个菜。 | H22: I want to take this dish to go. | I22: 我们可以打包这个菜吗？ | J22: Can we take this to go? | L22: 打包带走；帮我打包；可以打包
A23: 22 | B23: 4 | C23: 看菜单 | D23: 服务员 | E23: fúwùyuán | F23: waiter; waitress; server | G23: 他是服务员。 | H23: He is a waiter. | I23: 我认识一位服务员。 | J23: I know a waiter. | L23: 一位服务员；找服务员；服务员来了
A24: 23 | B24: 4 | C24: 看菜单 | D24: 买单 | E24: mǎidān | F24: pay the bill | G24: 我想买单。 | H24: I would like to pay the bill. | I24: 我们可以买单吗？ | J24: Can we pay the bill? | L24: 服务员买单；请买单；买单结账
A25: 24 | B25: 4 | C25: 看菜单 | D25: 一共 | E25: yígòng | F25: in total | G25: 一共五十块。 | H25: It is 50 yuan in total. | I25: 我们一共三个人。 | J25: There are three of us in total. | L25: 一共多少钱；一共有；一共需要
A26: 25 | B26: 4 | C26: 看菜单 | D26: 多少钱 | E26: duōshao qián | F26: how much | G26: 这个多少钱？ | H26: How much is this? | I26: 一斤苹果多少钱？ | J26: How much is a jin of apples? | L26: 多少钱一个；多少钱一斤；一共多少钱
A27: 26 | B27: 4 | C27: 看菜单 | D27: 块/元 | E27: kuài/yuán | F27: yuan (RMB); colloquial/formal money unit | G27: 这个十块。 | H27: This is ten yuan. | I27: 一共五十元。 | J27: The total is 50 yuan. | L27: 十块钱；二十元；一百元
A28: 27 | B28: 5 | C28: 描述菜品味道 | D28: 辣 | E28: là | F28: spicy | G28: 这个很辣。 | H28: This is very spicy. | I28: 那个不太辣。 | J28: That one is not very spicy. | L28: 很辣；比较辣；太辣了
A29: 28 | B29: 5 | C29: 描述菜品味道 | D29: 很 | E29: hěn | F29: very | G29: 这个很好。 | H29: This is very good. | I29: 今天很热。 | J29: It is very hot today. | L29: 很好；很喜欢；很漂亮
A30: 29 | B30: 5 | C30: 描述菜品味道 | D30: 不 | E30: bù | F30: not; no | G30: 我不去。 | H30: I am not going. | I30: 这个不贵。 | J30: This is not expensive. | L30: 不是；不要；不喜欢
... A32: 31 | B32: 5 | C32: 描述菜品味道 | D32: 甜 | E32: tián | F32: sweet | G32: 这个很甜。 | H32: This is very sweet. | I32: 那个不太甜。 | J32: That one is not very sweet. | L32: 很甜；比较甜；太甜了
A33: 32 | B33: 5 | C33: 描述菜品味道 | D33: 回锅肉 | E33: huíguōròu | F33: twice-cooked pork | G33: 我想吃回锅肉。 | H33: I want to eat twice-cooked pork. | I33: 我要一份回锅肉。 | J33: I'd like one serving of twice-cooked pork. | K33: 教材菜名 | L33: 吃回锅肉；一份回锅肉；喜欢回锅肉
A34: 33 | B34: 5 | C34: 描述菜品味道 | D34: 喜欢 | E34: xǐhuān | F34: like | G34: 我想喜欢这个菜。 | H34: I like this dish. | I34: 我们可以喜欢这个菜吗？ | J34: Do you like this dish? | L34: 很喜欢；最喜欢；喜欢吃
A35: 34 | B35: 5 | C35: 描述菜品味道 | D35: 也 | E35: yě | F35: also | G35: 我也喜欢。 | H35: I like it too. | I35: 他也是学生。 | J35: He is also a student. | L35: 也好；也可以；也喜欢
A36: 35 | B36: 5 | C36: 描述菜品味道 | D36: 但是 | E36: dànshì | F36: but | G36: 我喜欢，但是有点儿贵。 | H36: I like it, but it is a little expensive. | I36: 他想去，但是没时间。 | J36: He wants to go, but he has no time. | L36: 但是我；但是不；虽然…但是…
A37: 36 | B37: 5 | C37: 描述菜品味道 | D37: 更 | E37: gèng | F37: more; even more | G37: 这个更好。 | H37: This one is better. | I37: 今天更冷。 | J37: It is colder today. | L37: 更好；更多；更方便
A38: 37 | B38: 5 | C38: 描述菜品味道 | D38: 过 | E38: guò | F38: aspect particle: have done before | G38: 我去过北京。 | H38: I have been to Beijing. | I38: 请过马路。 | J38: Please cross the road. | L38: 去过；吃过；过马路
A39: 38 | B39: 5 | C39: 描述菜品味道 | D39: 的 | E39: de | F39: structural particle | G39: 这是我的。 | H39: This is mine. | I39: 红色的很好看。 | J39: The red one looks nice. | L39: 我的；红色的；新的
A40: 39 | B40: 5 | C40: 描述菜品味道 | D40: 酸甜 | E40: suāntián | F40: sweet and sour | G40: 这个很酸甜。 | H40: This is very sweet and sour. | I40: 那个不太酸甜。 | J40: That one is not very sweet and sour. | L40: 很酸甜；比较酸甜；太酸甜了
A41: 40 | B41: 5 | C41: 描述菜品味道 | D41: 呢 | E41: ne | F41: particle used in questions/topics | G41: 你呢？ | H41: And you? | I41: 他在哪儿呢？ | J41: Where is he? | L41: 你呢；在哪儿呢；怎么样呢
A42: 41 | B42: 5 | C42: 描述菜品味道 | D42: 特别 | E42: tèbié | F42: especially; special | G42: 这个特别好。 | H42: This is especially good. | I42: 我特别喜欢。 | J42: I especially like it. | L42: 特别好；特别喜欢；特别方便
A43: 42 | B43: 5 | C43: 描述菜品味道 | D43: 下次 | E43: xiàcì | F43: next time | G43: 下次见！ | H43: See you next time! | I43: 我们下次再去。 | J43: We will go again next time. | L43: 下次见；下次再说；下次来
...

Sheet 课次统计
A1: 课次 | B1: 课文 | C1: 词条数 | D1: 教材PDF词汇页
A2: 4 | B2: 看菜单 | C2: =COUNTIF(生存汉语词汇表!$B$2:$B$641,A2) -> 26 | D2: 13、15
A3: 5 | B3: 描述菜品味道 | C3: =COUNTIF(生存汉语词汇表!$B$2:$B$641,A3) -> 22 | D3: 18、19、20
A4: 6 | B4: 餐具 | C4: =COUNTIF(生存汉语词汇表!$B$2:$B$641,A4) -> 8 | D4: 24
A5: 7 | B5: 菜名和食材 | C5: =COUNTIF(生存汉语词汇表!$B$2:$B$641,A5) -> 30 | D5: 28、31
A6: 8 | B6: 在餐馆用餐 | C6: =COUNTIF(生存汉语词汇表!$B$2:$B$641,A6) -> 13 | D6: 36
A7: 9 | B7: 方位和地址 | C7: =COUNTIF(生存汉语词汇表!$B$2:$B$641,A7) -> 28 | D7: 40、42
A8: 10 | B8: 问路 | C8: =COUNTIF(生存汉语词汇表!$B$2:$B$641,A8) -> 14 | D8: 46
A9: 11 | B9: 打车 | C9: =COUNTIF(生存汉语词汇表!$B$2:$B$641,A9) -> 17 | D9: 49、51
A10: 12 | B10: 坐公交车 | C10: =COUNTIF(生存汉语词汇表!$B$2:$B$641,A10) -> 14 | D10: 54
A11: 13 | B11: 坐地铁 | C11: =COUNTIF(生存汉语词汇表!$B$2:$B$641,A11) -> 18 | D11: 57、59、60
A12: 14 | B12: 坐火车 | C12: =COUNTIF(生存汉语词汇表!$B$2:$B$641,A12) -> 15 | D12: 63、65
A13: 15 | B13: 坐飞机 | C13: =COUNTIF(生存汉语词汇表!$B$2:$B$641,A13) -> 28 | D13: 69、71
... A37: 39 | B37: 属相（十二生肖） | C37: =COUNTIF(生存汉语词汇表!$B$2:$B$641,A37) -> 10 | D37: 195
A38: 合计（按每课出现顺序，含重复词） | C38: =SUM(C2:C37) -> 640 | D38: 第1–3课为拼音教学，无正式词汇表

Sheet 说明
A1: 项目 | B1: 内容
A2: 教材 | B2: 《生存汉语一本通》 / An All-in-One Guide to Survival Chinese
A3: 整理范围 | B3: 第1–3课为拼音（韵母、声母、声调）教学，没有正式“动作/Movements”词汇表；主表从第4课《看菜单》整理至第39课《属相（十二生肖）》.
A4: 排序规则 | B4: 严格按每一课词汇表/动作表中的出现顺序整理；同一个词如果在后续课程再次出现，仍保留，便于直接按课制作闪卡。
A5: 主表规模 | B5: 640条按课出现词条（含重复）；579个唯一词形。
A6: 英文解释 | B6: 以教材英文释义为基准；扫描/OCR造成的明显错字已做规范化，个别释义为便于初学者理解做了简化。
A7: 拼音 | B7: 统一使用带声调拼音；对“行李、头发、发型、调皮、空、出差、重要”等多音字/轻声词进行了人工校正。
A8: 例句原则 | B8: 每个词提供2个原创、高频、短句；尽量使用本书或非常基础的生存汉语词汇，不使用复杂句式，适合直接改造成闪卡。
A9: 最常见词语搭配 | B9: 每词提供3个常见搭配/固定组合；量词、方位词、交通、看病、购物、酒店等场景优先使用真实生活中的高频搭配。
A10: 星号/专名 | B10: 教材中带“*”的菜名、地名、专名等保留，并在“备注”列标记，方便教师按学生水平决定是否纳入必背。
A11: 使用建议 | B11: 做闪卡时可将“汉字+拼音+英文解释”作为正面/核心信息，将两个例句和三个搭配作为背面扩展。
